<?xml version='1.0'?>
<sdf version='1.6'>

    <!-- ******************** ROBOT MODEL ******************** -->

    <model name='robot_engrais'>

        <!-- ******************** BODY LINK ******************** -->

        <link name='body'>
            <inertial>
                <mass>20</mass>
                <inertia>
                    <ixx>2.083333333</ixx>
                    <ixy>0</ixy>
                    <ixz>0</ixz>
                    <iyy>7.083333333</iyy>
                    <iyz>0</iyz>
                    <izz>8.333333333</izz>
                </inertia>
                <pose frame=''>0 0 0 0 -0 0</pose>
            </inertial>
            <pose frame=''>-0.295627 -0.002357 0.533914 0 -0 0</pose>
            <gravity>1</gravity>
            <self_collide>0</self_collide>
            <kinematic>0</kinematic>
            <enable_wind>0</enable_wind>
            <visual name='visual'>
                <pose frame=''>0 0 0 0 -0 0</pose>
                <geometry>
                    <box>
                        <size>2 1 0.5</size>
                    </box>
                </geometry>
                <material>
                    <lighting>1</lighting>
                    <script>
                        <uri>file://media/materials/scripts/gazebo.material</uri>
                        <name>Gazebo/Grey</name>
                    </script>
                    <shader type='pixel'>
                        <normal_map>__default__</normal_map>
                    </shader>
                    <ambient>0.3 0.3 0.3 1</ambient>
                    <diffuse>0.7 0.7 0.7 1</diffuse>
                    <specular>0.01 0.01 0.01 1</specular>
                    <emissive>0 0 0 1</emissive>
                </material>
                <transparency>0</transparency>
                <cast_shadows>1</cast_shadows>
            </visual>
            <collision name='collision'>
                <laser_retro>0</laser_retro>
                <max_contacts>10</max_contacts>
                <pose frame=''>0 0 0 0 -0 0</pose>
                <geometry>
                    <box>
                        <size>2 1 0.5</size>
                    </box>
                </geometry>
                <surface>
                    <friction>
                        <ode>
                            <mu>1</mu>
                            <mu2>1</mu2>
                            <fdir1>0 0 0</fdir1>
                            <slip1>0</slip1>
                            <slip2>0</slip2>
                        </ode>
                        <torsional>
                            <coefficient>1</coefficient>
                            <patch_radius>0</patch_radius>
                            <surface_radius>0</surface_radius>
                            <use_patch_radius>1</use_patch_radius>
                            <ode>
                                <slip>0</slip>
                            </ode>
                        </torsional>
                    </friction>
                    <bounce>
                        <restitution_coefficient>0</restitution_coefficient>
                        <threshold>1e+06</threshold>
                    </bounce>
                    <contact>
                        <collide_without_contact>0</collide_without_contact>
                        <collide_without_contact_bitmask>1</collide_without_contact_bitmask>
                        <collide_bitmask>1</collide_bitmask>
                        <ode>
                            <soft_cfm>0</soft_cfm>
                            <soft_erp>0.2</soft_erp>
                            <kp>1e+13</kp>
                            <kd>1</kd>
                            <max_vel>0.01</max_vel>
                            <min_depth>0</min_depth>
                        </ode>
                        <bullet>
                            <split_impulse>1</split_impulse>
                            <split_impulse_penetration_threshold>-0.01</split_impulse_penetration_threshold>
                            <soft_cfm>0</soft_cfm>
                            <soft_erp>0.2</soft_erp>
                            <kp>1e+13</kp>
                            <kd>1</kd>
                        </bullet>
                    </contact>
                </surface>
            </collision>
        </link>

        <!-- ******************** WHEEL 1 LINK ******************** -->

        <link name='wheel_1'>
            <inertial>
                <mass>3</mass>
                <inertia>
                    <ixx>0.083125</ixx>
                    <ixy>0</ixy>
                    <ixz>0</ixz>
                    <iyy>0.083125</iyy>
                    <iyz>0</iyz>
                    <izz>0.135</izz>
                </inertia>
                <pose frame=''>0 0 0 0 -0 0</pose>
            </inertial>
            <pose frame=''>0.404373 0.637672 0.433914 1.5707 -0 0</pose>
            <gravity>1</gravity>
            <self_collide>0</self_collide>
            <kinematic>0</kinematic>
            <enable_wind>0</enable_wind>
            <visual name='visual'>
                <pose frame=''>0 0 0 0 -0 0</pose>
                <geometry>
                    <cylinder>
                        <radius>0.3</radius>
                        <length>0.25</length>
                    </cylinder>
                </geometry>
                <material>
                    <lighting>1</lighting>
                    <script>
                        <uri>file://media/materials/scripts/gazebo.material</uri>
                        <name>Gazebo/Grey</name>
                    </script>
                    <shader type='pixel'>
                        <normal_map>__default__</normal_map>
                    </shader>
                    <ambient>0.3 0.3 0.3 1</ambient>
                    <diffuse>0.7 0.7 0.7 1</diffuse>
                    <specular>0.01 0.01 0.01 1</specular>
                    <emissive>0 0 0 1</emissive>
                </material>
                <transparency>0</transparency>
                <cast_shadows>1</cast_shadows>
            </visual>
            <collision name='collision'>
                <laser_retro>0</laser_retro>
                <max_contacts>10</max_contacts>
                <pose frame=''>0 0 0 0 -0 0</pose>
                <geometry>
                    <cylinder>
                        <radius>0.3</radius>
                        <length>0.25</length>
                    </cylinder>
                </geometry>
                <surface>
                    <friction>
                        <ode>
                            <mu>1</mu>
                            <mu2>1</mu2>
                            <fdir1>0 0 0</fdir1>
                            <slip1>0</slip1>
                            <slip2>0</slip2>
                        </ode>
                        <torsional>
                            <coefficient>1</coefficient>
                            <patch_radius>0</patch_radius>
                            <surface_radius>0</surface_radius>
                            <use_patch_radius>1</use_patch_radius>
                            <ode>
                                <slip>0</slip>
                            </ode>
                        </torsional>
                    </friction>
                    <bounce>
                        <restitution_coefficient>0</restitution_coefficient>
                        <threshold>1e+06</threshold>
                    </bounce>
                    <contact>
                        <collide_without_contact>0</collide_without_contact>
                        <collide_without_contact_bitmask>1</collide_without_contact_bitmask>
                        <collide_bitmask>1</collide_bitmask>
                        <ode>
                            <soft_cfm>0</soft_cfm>
                            <soft_erp>0.2</soft_erp>
                            <kp>1e+13</kp>
                            <kd>1</kd>
                            <max_vel>0.01</max_vel>
                            <min_depth>0</min_depth>
                        </ode>
                        <bullet>
                            <split_impulse>1</split_impulse>
                            <split_impulse_penetration_threshold>-0.01</split_impulse_penetration_threshold>
                            <soft_cfm>0</soft_cfm>
                            <soft_erp>0.2</soft_erp>
                            <kp>1e+13</kp>
                            <kd>1</kd>
                        </bullet>
                    </contact>
                </surface>
            </collision>
        </link>

        <!-- ******************** WHEEL 2 LINK ******************** -->

        <link name='wheel_2'>
            <inertial>
                <mass>3</mass>
                <inertia>
                    <ixx>0.083125</ixx>
                    <ixy>0</ixy>
                    <ixz>0</ixz>
                    <iyy>0.083125</iyy>
                    <iyz>0</iyz>
                    <izz>0.135</izz>
                </inertia>
                <pose frame=''>0 0 0 0 -0 0</pose>
            </inertial>
            <pose frame=''>0.404373 -0.627386 0.433914 1.5707 -0 0</pose>
            <gravity>1</gravity>
            <self_collide>0</self_collide>
            <kinematic>0</kinematic>
            <enable_wind>0</enable_wind>
            <visual name='visual'>
                <pose frame=''>0 0 0 0 -0 0</pose>
                <geometry>
                    <cylinder>
                        <radius>0.3</radius>
                        <length>0.25</length>
                    </cylinder>
                </geometry>
                <material>
                    <lighting>1</lighting>
                    <script>
                        <uri>file://media/materials/scripts/gazebo.material</uri>
                        <name>Gazebo/Grey</name>
                    </script>
                    <shader type='pixel'>
                        <normal_map>__default__</normal_map>
                    </shader>
                    <ambient>0.3 0.3 0.3 1</ambient>
                    <diffuse>0.7 0.7 0.7 1</diffuse>
                    <specular>0.01 0.01 0.01 1</specular>
                    <emissive>0 0 0 1</emissive>
                </material>
                <transparency>0</transparency>
                <cast_shadows>1</cast_shadows>
            </visual>
            <collision name='collision'>
                <laser_retro>0</laser_retro>
                <max_contacts>10</max_contacts>
                <pose frame=''>0 0 0 0 -0 0</pose>
                <geometry>
                    <cylinder>
                        <radius>0.3</radius>
                        <length>0.25</length>
                    </cylinder>
                </geometry>
                <surface>
                    <friction>
                        <ode>
                            <mu>1</mu>
                            <mu2>1</mu2>
                            <fdir1>0 0 0</fdir1>
                            <slip1>0</slip1>
                            <slip2>0</slip2>
                        </ode>
                        <torsional>
                            <coefficient>1</coefficient>
                            <patch_radius>0</patch_radius>
                            <surface_radius>0</surface_radius>
                            <use_patch_radius>1</use_patch_radius>
                            <ode>
                                <slip>0</slip>
                            </ode>
                        </torsional>
                    </friction>
                    <bounce>
                        <restitution_coefficient>0</restitution_coefficient>
                        <threshold>1e+06</threshold>
                    </bounce>
                    <contact>
                        <collide_without_contact>0</collide_without_contact>
                        <collide_without_contact_bitmask>1</collide_without_contact_bitmask>
                        <collide_bitmask>1</collide_bitmask>
                        <ode>
                            <soft_cfm>0</soft_cfm>
                            <soft_erp>0.2</soft_erp>
                            <kp>1e+13</kp>
                            <kd>1</kd>
                            <max_vel>0.01</max_vel>
                            <min_depth>0</min_depth>
                        </ode>
                        <bullet>
                            <split_impulse>1</split_impulse>
                            <split_impulse_penetration_threshold>-0.01</split_impulse_penetration_threshold>
                            <soft_cfm>0</soft_cfm>
                            <soft_erp>0.2</soft_erp>
                            <kp>1e+13</kp>
                            <kd>1</kd>
                        </bullet>
                    </contact>
                </surface>
            </collision>
        </link>

        <!-- ******************** SPHERE LINK ******************** -->

        <link name='sphere'>
            <inertial>
                <mass>2</mass>
                <inertia>
                    <ixx>0.032</ixx>
                    <ixy>0</ixy>
                    <ixz>0</ixz>
                    <iyy>0.032</iyy>
                    <iyz>0</iyz>
                    <izz>0.032</izz>
                </inertia>
                <pose frame=''>0 0 0 0 -0 0</pose>
            </inertial>
            <pose frame=''>-1.09563 -0.002357 0.333914 0 -0 0</pose>
            <gravity>1</gravity>
            <self_collide>0</self_collide>
            <kinematic>0</kinematic>
            <enable_wind>0</enable_wind>
            <visual name='visual'>
                <pose frame=''>0 0 0 0 -0 0</pose>
                <geometry>
                    <sphere>
                        <radius>0.2</radius>
                    </sphere>
                </geometry>
                <material>
                    <lighting>1</lighting>
                    <script>
                        <uri>file://media/materials/scripts/gazebo.material</uri>
                        <name>Gazebo/Grey</name>
                    </script>
                    <shader type='pixel'>
                        <normal_map>__default__</normal_map>
                    </shader>
                    <ambient>0.3 0.3 0.3 1</ambient>
                    <diffuse>0.7 0.7 0.7 1</diffuse>
                    <specular>0.01 0.01 0.01 1</specular>
                    <emissive>0 0 0 1</emissive>
                </material>
                <transparency>0</transparency>
                <cast_shadows>1</cast_shadows>
            </visual>
            <collision name='collision'>
                <laser_retro>0</laser_retro>
                <max_contacts>10</max_contacts>
                <pose frame=''>0 0 0 0 -0 0</pose>
                <geometry>
                    <sphere>
                        <radius>0.2</radius>
                    </sphere>
                </geometry>
                <surface>
                    <friction>
                        <ode>
                            <mu>1</mu>
                            <mu2>1</mu2>
                            <fdir1>0 0 0</fdir1>
                            <slip1>0</slip1>
                            <slip2>0</slip2>
                        </ode>
                        <torsional>
                            <coefficient>1</coefficient>
                            <patch_radius>0</patch_radius>
                            <surface_radius>0</surface_radius>
                            <use_patch_radius>1</use_patch_radius>
                            <ode>
                                <slip>0</slip>
                            </ode>
                        </torsional>
                    </friction>
                    <bounce>
                        <restitution_coefficient>0</restitution_coefficient>
                        <threshold>1e+06</threshold>
                    </bounce>
                    <contact>
                        <collide_without_contact>0</collide_without_contact>
                        <collide_without_contact_bitmask>1</collide_without_contact_bitmask>
                        <collide_bitmask>1</collide_bitmask>
                        <ode>
                            <soft_cfm>0</soft_cfm>
                            <soft_erp>0.2</soft_erp>
                            <kp>1e+13</kp>
                            <kd>1</kd>
                            <max_vel>0.01</max_vel>
                            <min_depth>0</min_depth>
                        </ode>
                        <bullet>
                            <split_impulse>1</split_impulse>
                            <split_impulse_penetration_threshold>-0.01</split_impulse_penetration_threshold>
                            <soft_cfm>0</soft_cfm>
                            <soft_erp>0.2</soft_erp>
                            <kp>1e+13</kp>
                            <kd>1</kd>
                        </bullet>
                    </contact>
                </surface>
            </collision>
        </link>

        <!-- ******************** SENSOR MODEL ******************** -->
        <model name='lidar_engrais'>

            <!-- ******************** BASE LINK ******************** -->

            <link name='base'>
                <pose frame=''>0 0 0.029335 0 -0 0</pose>
                <inertial>
                    <mass>1.2</mass>
                    <inertia>
                        <ixx>0.00108747</ixx>
                        <iyy>0.00108747</iyy>
                        <izz>0.00109244</izz>
                        <ixy>0</ixy>
                        <ixz>0</ixz>
                        <iyz>0</iyz>
                    </inertia>
                </inertial>
                <collision name='base_collision'>
                    <geometry>
                        <cylinder>
                            <radius>0.04267</radius>
                            <length>0.05867</length>
                        </cylinder>
                    </geometry>
                </collision>
                <visual name='base_visual'>
                    <geometry>
                        <cylinder>
                            <radius>0.04267</radius>
                            <length>0.05867</length>
                        </cylinder>
                    </geometry>
                </visual>
            </link>

            <!-- ******************** TOP LINK ******************** -->

            <link name='top'>
                <sensor name='LIDAR' type='ray'>
                    <pose frame=''>0 0 -0.004645 0 -0 0</pose>
                    <visualize>1</visualize>
                    <update_rate>30</update_rate>
                    <ray>
                        <scan>
                            <horizontal>
                                <samples>40</samples>
                                <resolution>1</resolution>
                                <min_angle>-1.57079632679</min_angle>
                                <max_angle>1.57079632679</max_angle>
                            </horizontal>
                        </scan>
                        <range>
                            <min>0.05</min>
                            <max>10</max>
                            <resolution>0.02</resolution>
                        </range>
                    </ray>
                </sensor>
                <pose frame=''>0 0 0.095455 0 -0 0</pose>
                <inertial>
                    <mass>0.1</mass>
                    <inertia>
                        <ixx>9.0623e-05</ixx>
                        <iyy>9.0623e-05</iyy>
                        <izz>9.1036e-05</izz>
                        <ixy>0</ixy>
                        <ixz>0</ixz>
                        <iyz>0</iyz>
                    </inertia>
                </inertial>
                <collision name='top_collision'>
                    <geometry>
                        <cylinder>
                            <radius>0.04267</radius>
                            <length>0.07357</length>
                        </cylinder>
                    </geometry>
                </collision>
                <visual name='top_visual'>
                    <geometry>
                        <cylinder>
                            <radius>0.04267</radius>
                            <length>0.07357</length>
                        </cylinder>
                    </geometry>
                </visual>
            </link>

            <!-- ******************** JOINT SENSOR BASE TOP ******************** -->

            <joint name='base_JOINT_top' type='revolute'>
                <pose frame=''>0 0 -0.036785 0 -0 0</pose>
                <parent>base</parent>
                <child>top</child>
                <axis>
                    <xyz>0 0 1</xyz>
                    <limit>
                        <lower>-1e+16</lower>
                        <upper>1e+16</upper>
                    </limit>
                    <use_parent_model_frame>0</use_parent_model_frame>
                </axis>
            </joint>
            <pose frame=''>0.582506 -0.005572 0.764343 0 -0 0</pose>
        </model>

        <!-- ******************** JOINT ROBOT BODY WHEEL 1 ******************** -->

        <joint name='body_JOINT_wheel_1' type='revolute'>
            <parent>body</parent>
            <child>wheel_1</child>
            <pose frame=''>0 0 0 0 -0 0</pose>
            <axis>
                <xyz>-0 -0 -1</xyz>
                <use_parent_model_frame>0</use_parent_model_frame>
                <limit>
                    <lower>-1.79769e+308</lower>
                    <upper>1.79769e+308</upper>
                    <effort>-1</effort>
                    <velocity>-1</velocity>
                </limit>
                <dynamics>
                    <spring_reference>0</spring_reference>
                    <spring_stiffness>0</spring_stiffness>
                    <damping>0</damping>
                </dynamics>
            </axis>
            <physics>
                <ode>
                    <limit>
                        <cfm>0</cfm>
                        <erp>0.2</erp>
                    </limit>
                    <suspension>
                        <cfm>0</cfm>
                        <erp>0.2</erp>
                    </suspension>
                </ode>
            </physics>
        </joint>

        <!-- ******************** JOINT ROBOT BODY WHEEL 2 ******************** -->

        <joint name='body_JOINT_wheel_2' type='revolute'>
            <parent>body</parent>
            <child>wheel_2</child>
            <pose frame=''>0 0 0 0 -0 0</pose>
            <axis>
                <xyz>-0 -0 -1</xyz>
                <use_parent_model_frame>0</use_parent_model_frame>
                <limit>
                    <lower>-1.79769e+308</lower>
                    <upper>1.79769e+308</upper>
                    <effort>-1</effort>
                    <velocity>-1</velocity>
                </limit>
                <dynamics>
                    <spring_reference>0</spring_reference>
                    <spring_stiffness>0</spring_stiffness>
                    <damping>0</damping>
                </dynamics>
            </axis>
            <physics>
                <ode>
                    <limit>
                        <cfm>0</cfm>
                        <erp>0.2</erp>
                    </limit>
                    <suspension>
                        <cfm>0</cfm>
                        <erp>0.2</erp>
                    </suspension>
                </ode>
            </physics>
        </joint>

        <!-- ******************** JOINT ROBOT BODY SPHERE ******************** -->

        <joint name='body_JOINT_sphere' type='ball'>
            <parent>body</parent>
            <child>sphere</child>
            <pose frame=''>0 0 0 0 -0 0</pose>
            <physics>
                <ode>
                    <limit>
                        <cfm>0</cfm>
                        <erp>0.2</erp>
                    </limit>
                    <suspension>
                        <cfm>0</cfm>
                        <erp>0.2</erp>
                    </suspension>
                </ode>
            </physics>
        </joint>

        <!-- ******************** JOINT ROBOT BODY LIDAR ******************** -->

        <joint name='body_JOINT_sensor' type='fixed'>
            <parent>body</parent>
            <child>lidar_engrais::base</child>
            <pose frame=''>0 0 0 0 -0 0</pose>
            <physics>
                <ode>
                    <limit>
                        <cfm>0</cfm>
                        <erp>0.2</erp>
                    </limit>
                    <suspension>
                        <cfm>0</cfm>
                        <erp>0.2</erp>
                    </suspension>
                </ode>
            </physics>
        </joint>
        <static>0</static>
        <allow_auto_disable>1</allow_auto_disable>
    </model>
</sdf>
